Workbook

Sheet Principal
A1: - | B1: EDT | C1: Fase | D1: Tarea | E1: Dias Plan | F1: Fecha Inicio Plan | G1: Fecha Final Plan | H1: % Avance Plan | I1: % Avance Real | J1: Status | M1: Diagrama de Grantt por Fase (en semanas)
A2: 1 | B2: 45292 | C2: Análisis | D2: Identificación de Requerimientos Funcionales y No Funcionales | E2: =NETWORKDAYS(F2,G2) -> 2 | F2: 45806 | G2: 45807 | H2: =ROUNDUP(IF(E2>0,IF(Resumen!$A$2>G2,100%,IF(Resumen!$A$2<F2,0%,(100%/E2)*(NETWORKDAYS(F2,Resumen!$A$2)))),0%),2) -> 1 | I2: 1 | J2: =IF(E2>0,IF(AND(H2=I2,H2=100%),"Terminado",IF(AND(H2=I2,H2<100,H2>0),"Proceso",IF(AND(H2>I2,H2<100,H2>0),"Retrasado","Plan"))),"") -> Terminado | L2: Fase | N2: 45806 | O2: 45813 | P2: 45820 | Q2: 45827 | R2: 45834 | S2: 45841 | T2: 45848 | U2: 45855 | V2: 45862 | W2: 45869 | X2: 45876 | Y2: 45883
A3: 2 | B3: 45689 | C3: Análisis | D3: Documento Formal de Requerimientos | E3: =NETWORKDAYS(F3,G3) -> 6 | F3: 45807 | G3: 45814 | H3: =ROUNDUP(IF(E3>0,IF(Resumen!$A$2>G3,100%,IF(Resumen!$A$2<F3,0%,(100%/E3)*(NETWORKDAYS(F3,Resumen!$A$2)))),0%),2) -> 1 | I3: 1 | J3: =IF(E3>0,IF(AND(H3=I3,H3=100%),"Terminado",IF(AND(H3=I3,H3<100,H3>0),"Proceso",IF(AND(H3>I3,H3<100,H3>0),"Retrasado","Plan"))),"") -> Terminado
A4: 3 | B4: 45383 | C4: Análisis | D4: Acta de Constitución | E4: =NETWORKDAYS(F4,G4) -> 2 | F4: 45826 | G4: 45827 | H4: =ROUNDUP(IF(E4>0,IF(Resumen!$A$2>G4,100%,IF(Resumen!$A$2<F4,0%,(100%/E4)*(NETWORKDAYS(F4,Resumen!$A$2)))),0%),2) -> 1 | I4: 1 | J4: =IF(E4>0,IF(AND(H4=I4,H4=100%),"Terminado",IF(AND(H4=I4,H4<100,H4>0),"Proceso",IF(AND(H4>I4,H4<100,H4>0),"Retrasado","Plan"))),"") -> Terminado
A5: 4 | B5: 45778 | C5: Análisis | D5: Estructura del Desgloce de Trabajo | E5: =NETWORKDAYS(F5,G5) -> 3 | F5: 45832 | G5: 45834 | H5: =ROUNDUP(IF(E5>0,IF(Resumen!$A$2>G5,100%,IF(Resumen!$A$2<F5,0%,(100%/E5)*(NETWORKDAYS(F5,Resumen!$A$2)))),0%),2) -> 1 | I5: 1 | J5: =IF(E5>0,IF(AND(H5=I5,H5=100%),"Terminado",IF(AND(H5=I5,H5<100,H5>0),"Proceso",IF(AND(H5>I5,H5<100,H5>0),"Retrasado","Plan"))),"") -> Terminado | M5: Análisis
A6: 5 | B6: 45444 | C6: Análisis | D6: Mapa de Interesados | E6: =NETWORKDAYS(F6,G6) -> 3 | F6: 45832 | G6: 45834 | H6: =ROUNDUP(IF(E6>0,IF(Resumen!$A$2>G6,100%,IF(Resumen!$A$2<F6,0%,(100%/E6)*(NETWORKDAYS(F6,Resumen!$A$2)))),0%),2) -> 1 | I6: 1 | J6: =IF(E6>0,IF(AND(H6=I6,H6=100%),"Terminado",IF(AND(H6=I6,H6<100,H6>0),"Proceso",IF(AND(H6>I6,H6<100,H6>0),"Retrasado","Plan"))),"") -> Terminado | M6: Diseño
A7: 6 | B7: 45839 | C7: Análisis | D7: Cronograma | E7: =NETWORKDAYS(F7,G7) -> 4 | F7: 45833 | G7: 45838 | H7: =ROUNDUP(IF(E7>0,IF(Resumen!$A$2>G7,100%,IF(Resumen!$A$2<F7,0%,(100%/E7)*(NETWORKDAYS(F7,Resumen!$A$2)))),0%),2) -> 1 | I7: 1 | J7: =IF(E7>0,IF(AND(H7=I7,H7=100%),"Terminado",IF(AND(H7=I7,H7<100,H7>0),"Proceso",IF(AND(H7>I7,H7<100,H7>0),"Retrasado","Plan"))),"") -> Terminado | M7: Ejecución
A8: 7 | B8: 45659 | C8: Diseño | D8: Diagrama de Clases | E8: =NETWORKDAYS(F8,G8) -> 3 | F8: 45812 | G8: 45814 | H8: =ROUNDUP(IF(E8>0,IF(Resumen!$A$2>G8,100%,IF(Resumen!$A$2<F8,0%,(100%/E8)*(NETWORKDAYS(F8,Resumen!$A$2)))),0%),2) -> 1 | I8: 1 | J8: =IF(E8>0,IF(AND(H8=I8,H8=100%),"Terminado",IF(AND(H8=I8,H8<100,H8>0),"Proceso",IF(AND(H8>I8,H8<100,H8>0),"Retrasado","Plan"))),"") -> Terminado | M8: Liberación
A9: 8 | B9: 45324 | C9: Diseño | D9: Diseño de pantallas moviles | E9: =NETWORKDAYS(F9,G9) -> 18 | F9: 45810 | G9: 45833 | H9: =ROUNDUP(IF(E9>0,IF(Resumen!$A$2>G9,100%,IF(Resumen!$A$2<F9,0%,(100%/E9)*(NETWORKDAYS(F9,Resumen!$A$2)))),0%),2) -> 1 | I9: 1 | J9: =IF(E9>0,IF(AND(H9=I9,H9=100%),"Terminado",IF(AND(H9=I9,H9<100,H9>0),"Proceso",IF(AND(H9>I9,H9<100,H9>0),"Retrasado","Plan"))),"") -> Terminado | M9: Pruebas
A10: 9 | B10: 2.2.1 | C10: Diseño | D10: Móvil - Inicio de sesión | E10: =NETWORKDAYS(F10,G10) -> 2 | F10: 45811 | G10: 45812 | H10: =ROUNDUP(IF(E10>0,IF(Resumen!$A$2>G10,100%,IF(Resumen!$A$2<F10,0%,(100%/E10)*(NETWORKDAYS(F10,Resumen!$A$2)))),0%),2) -> 1 | I10: 1 | J10: =IF(E10>0,IF(AND(H10=I10,H10=100%),"Terminado",IF(AND(H10=I10,H10<100,H10>0),"Proceso",IF(AND(H10>I10,H10<100,H10>0),"Retrasado","Plan"))),"") -> Terminado | M10: Fecha
A11: 10 | B11: 2.2.2 | C11: Diseño | D11: Móvil - Gestión de perfil | E11: =NETWORKDAYS(F11,G11) -> 2 | F11: 45812 | G11: 45813 | H11: =ROUNDUP(IF(E11>0,IF(Resumen!$A$2>G11,100%,IF(Resumen!$A$2<F11,0%,(100%/E11)*(NETWORKDAYS(F11,Resumen!$A$2)))),0%),2) -> 1 | I11: 1 | J11: =IF(E11>0,IF(AND(H11=I11,H11=100%),"Terminado",IF(AND(H11=I11,H11<100,H11>0),"Proceso",IF(AND(H11>I11,H11<100,H11>0),"Retrasado","Plan"))),"") -> Terminado
A12: 11 | B12: 2.2.3 | C12: Diseño | D12: Móvil - Registro de Usuario | E12: =NETWORKDAYS(F12,G12) -> 2 | F12: 45813 | G12: 45814 | H12: =ROUNDUP(IF(E12>0,IF(Resumen!$A$2>G12,100%,IF(Resumen!$A$2<F12,0%,(100%/E12)*(NETWORKDAYS(F12,Resumen!$A$2)))),0%),2) -> 1 | I12: 1 | J12: =IF(E12>0,IF(AND(H12=I12,H12=100%),"Terminado",IF(AND(H12=I12,H12<100,H12>0),"Proceso",IF(AND(H12>I12,H12<100,H12>0),"Retrasado","Plan"))),"") -> Terminado
A13: 12 | B13: 2.2.4 | C13: Diseño | D13: Móvil - Módulo del Perfil de Usuario | E13: =NETWORKDAYS(F13,G13) -> 2 | F13: 45817 | G13: 45818 | H13: =ROUNDUP(IF(E13>0,IF(Resumen!$A$2>G13,100%,IF(Resumen!$A$2<F13,0%,(100%/E13)*(NETWORKDAYS(F13,Resumen!$A$2)))),0%),2) -> 1 | I13: 1 | J13: =IF(E13>0,IF(AND(H13=I13,H13=100%),"Terminado",IF(AND(H13=I13,H13<100,H13>0),"Proceso",IF(AND(H13>I13,H13<100,H13>0),"Retrasado","Plan"))),"") -> Terminado
A14: 13 | B14: 2.2.5 | C14: Diseño | D14: Móvil - Pantalla Principal | E14: =NETWORKDAYS(F14,G14) -> 2 | F14: 45818 | G14: 45819 | H14: =ROUNDUP(IF(E14>0,IF(Resumen!$A$2>G14,100%,IF(Resumen!$A$2<F14,0%,(100%/E14)*(NETWORKDAYS(F14,Resumen!$A$2)))),0%),2) -> 1 | I14: 1 | J14: =IF(E14>0,IF(AND(H14=I14,H14=100%),"Terminado",IF(AND(H14=I14,H14<100,H14>0),"Proceso",IF(AND(H14>I14,H14<100,H14>0),"Retrasado","Plan"))),"") -> Terminado
A15: 14 | B15: 2.2.6 | C15: Diseño | D15: Móvil - Módulo de Alimentación | E15: =NETWORKDAYS(F15,G15) -> 2 | F15: 45819 | G15: 45820 | H15: =ROUNDUP(IF(E15>0,IF(Resumen!$A$2>G15,100%,IF(Resumen!$A$2<F15,0%,(100%/E15)*(NETWORKDAYS(F15,Resumen!$A$2)))),0%),2) -> 1 | I15: 1 | J15: =IF(E15>0,IF(AND(H15=I15,H15=100%),"Terminado",IF(AND(H15=I15,H15<100,H15>0),"Proceso",IF(AND(H15>I15,H15<100,H15>0),"Retrasado","Plan"))),"") -> Terminado
A16: 15 | B16: 2.2.7 | C16: Diseño | D16: Móvil - Módulo de Sueño | E16: =NETWORKDAYS(F16,G16) -> 2 | F16: 45820 | G16: 45821 | H16: =ROUNDUP(IF(E16>0,IF(Resumen!$A$2>G16,100%,IF(Resumen!$A$2<F16,0%,(100%/E16)*(NETWORKDAYS(F16,Resumen!$A$2)))),0%),2) -> 1 | I16: 1 | J16: =IF(E16>0,IF(AND(H16=I16,H16=100%),"Terminado",IF(AND(H16=I16,H16<100,H16>0),"Proceso",IF(AND(H16>I16,H16<100,H16>0),"Retrasado","Plan"))),"") -> Terminado
A17: 16 | B17: 2.2.8 | C17: Diseño | D17: Móvil - Módulo de Entrenamiento | E17: =NETWORKDAYS(F17,G17) -> 2 | F17: 45821 | G17: 45824 | H17: =ROUNDUP(IF(E17>0,IF(Resumen!$A$2>G17,100%,IF(Resumen!$A$2<F17,0%,(100%/E17)*(NETWORKDAYS(F17,Resumen!$A$2)))),0%),2) -> 1 | I17: 1 | J17: =IF(E17>0,IF(AND(H17=I17,H17=100%),"Terminado",IF(AND(H17=I17,H17<100,H17>0),"Proceso",IF(AND(H17>I17,H17<100,H17>0),"Retrasado","Plan"))),"") -> Terminado
A18: 17 | B18: 2.2.9 | C18: Diseño | D18: Móvil - Módulo de Pacientes | E18: =NETWORKDAYS(F18,G18) -> 2 | F18: 45824 | G18: 45825 | H18: =ROUNDUP(IF(E18>0,IF(Resumen!$A$2>G18,100%,IF(Resumen!$A$2<F18,0%,(100%/E18)*(NETWORKDAYS(F18,Resumen!$A$2)))),0%),2) -> 1 | I18: 1 | J18: =IF(E18>0,IF(AND(H18=I18,H18=100%),"Terminado",IF(AND(H18=I18,H18<100,H18>0),"Proceso",IF(AND(H18>I18,H18<100,H18>0),"Retrasado","Plan"))),"") -> Terminado
A19: 18 | B19: 2.2.10 | C19: Diseño | D19: Móvil - Restablecer Contraseña | E19: =NETWORKDAYS(F19,G19) -> 2 | F19: 45825 | G19: 45826 | H19: =ROUNDUP(IF(E19>0,IF(Resumen!$A$2>G19,100%,IF(Resumen!$A$2<F19,0%,(100%/E19)*(NETWORKDAYS(F19,Resumen!$A$2)))),0%),2) -> 1 | I19: 1 | J19: =IF(E19>0,IF(AND(H19=I19,H19=100%),"Terminado",IF(AND(H19=I19,H19<100,H19>0),"Proceso",IF(AND(H19>I19,H19<100,H19>0),"Retrasado","Plan"))),"") -> Terminado
A20: 19 | B20: 2.2.11 | C20: Diseño | D20: Móvil - Módulo de Notificaciones | E20: =NETWORKDAYS(F20,G20) -> 2 | F20: 45826 | G20: 45827 | H20: =ROUNDUP(IF(E20>0,IF(Resumen!$A$2>G20,100%,IF(Resumen!$A$2<F20,0%,(100%/E20)*(NETWORKDAYS(F20,Resumen!$A$2)))),0%),2) -> 1 | I20: 1 | J20: =IF(E20>0,IF(AND(H20=I20,H20=100%),"Terminado",IF(AND(H20=I20,H20<100,H20>0),"Proceso",IF(AND(H20>I20,H20<100,H20>0),"Retrasado","Plan"))),"") -> Terminado
A21: 20 | B21: 2.2.12 | C21: Diseño | D21: Móvil - Corrección de Diseños de Pantallas | E21: =NETWORKDAYS(F21,G21) -> 4 | F21: 45828 | G21: 45833 | H21: =ROUNDUP(IF(E21>0,IF(Resumen!$A$2>G21,100%,IF(Resumen!$A$2<F21,0%,(100%/E21)*(NETWORKDAYS(F21,Resumen!$A$2)))),0%),2) -> 1 | I21: 1 | J21: =IF(E21>0,IF(AND(H21=I21,H21=100%),"Terminado",IF(AND(H21=I21,H21<100,H21>0),"Proceso",IF(AND(H21>I21,H21<100,H21>0),"Retrasado","Plan"))),"") -> Terminado
A22: 21 | B22: 3.1 | C22: Ejecución | D22: Back-End-Realización de base de datos con JPA | E22: =NETWORKDAYS(F22,G22) -> 9 | F22: 45827 | G22: 45839 | H22: =ROUNDUP(IF(E22>0,IF(Resumen!$A$2>G22,100%,IF(Resumen!$A$2<F22,0%,(100%/E22)*(NETWORKDAYS(F22,Resumen!$A$2)))),0%),2) -> 1 | I22: 1 | J22: =IF(E22>0,IF(AND(H22=I22,H22=100%),"Terminado",IF(AND(H22=I22,H22<100,H22>0),"Proceso",IF(AND(H22>I22,H22<100,H22>0),"Retrasado","Plan"))),"") -> Terminado
... A42: 41 | B42: 5.3 | C42: Liberación | D42: Diseño de pantallas | E42: =NETWORKDAYS(F42,G42) -> 5 | F42: 45881 | G42: 45887 | H42: =ROUNDUP(IF(E42>0,IF(Resumen!$A$2>G42,100%,IF(Resumen!$A$2<F42,0%,(100%/E42)*(NETWORKDAYS(F42,Resumen!$A$2)))),0%),2) -> 1 | I42: 1 | J42: =IF(E42>0,IF(AND(H42=I42,H42=100%),"Terminado",IF(AND(H42=I42,H42<100,H42>0),"Proceso",IF(AND(H42>I42,H42<100,H42>0),"Retrasado","Plan"))),"") -> Terminado

Sheet Cronología 1

Sheet Resumen
A1: FechaStatus | B1: Fecha Inicio Plan | C1: Fecha Final Plan | D1: DuraciónPlan | E1: Factor Porcentual de Avance | F1: Dias Transcurridos | G1: Dias Faltantes
A2: 45887 | B2: =MIN(Principal!F:F) -> 45806 | C2: =MAX(Principal!G:G) -> 45887 | D2: =_xlfn.NETWORKDAYS.INTL(MIN(Principal!F:F),MAX(Principal!G:G)) -> 58 | E2: =(SUM(Principal!I:I)/100%)/SUM(Principal!H:H) -> 1 | F2: =_xlfn.NETWORKDAYS.INTL(MIN(Principal!F:F),A2) -> 58 | G2: =_xlfn.NETWORKDAYS.INTL(A2,MAX(Principal!G:G)) -> 1

Sheet Presupuesto consolidado
A1: Tarea | B1: Costo estimado (MXN)
A2: Análisis de Requerimientos | B2: 14375
A3: Diseño de Interfaz | B3: 20625
A4: Desarrollo (Back-End /Front-End) | B4: 35000
A5: Pruebas y validación | B5: 13750
A6: Documentacion | B6: 3125
A7: Contingencia(15%) | B7: =SUM(B2:B6)*0.15 -> 13031.25
A8: Total estimado del proyecto | B8: =SUM(B2:B6)+B7 -> 99906.25

Sheet Presupuesto Detallado
A1: Tarea | B1: Tarifa($MXN) | C1: Duración(hr) | D1: Subtotal
A2: Identificación de Requerimientos Funcionales y No Funcionales | B2: 156.25 | C2: 8 | D2: =B2*C2 -> 1250
A3: Documento Formal de Requerimientos | B3: 156.25 | C3: 28 | D3: =B3*C3 -> 4375
A4: Acta de Constitución | B4: 156.25 | C4: 8 | D4: =B4*C4 -> 1250
A5: Estructura del Desgloce de Trabajo | B5: 156.25 | C5: 12 | D5: =B5*C5 -> 1875
A6: Mapa de Interesados | B6: 156.25 | C6: 12 | D6: =B6*C6 -> 1875
A7: Cronograma | B7: 156.25 | C7: 24 | D7: =B7*C7 -> 3750 | E7: =SUM(D2:D7) -> 14375
A8: Diagrama de Clases | B8: 156.25 | C8: 12 | D8: =B8*C8 -> 1875
A9: Móvil - Inicio de sesión | B9: 156.25 | C9: 8 | D9: =B9*C9 -> 1250
A10: Móvil - Gestión de perfil | B10: 156.25 | C10: 8 | D10: =B10*C10 -> 1250
A11: Móvil - Registro de Usuario | B11: 156.25 | C11: 8 | D11: =B11*C11 -> 1250
A12: Móvil - Módulo del Perfil de Usuario | B12: 156.25 | C12: 8 | D12: =B12*C12 -> 1250
A13: Móvil - Pantalla Principal | B13: 156.25 | C13: 8 | D13: =B13*C13 -> 1250
A14: Móvil - Módulo de Alimentación | B14: 156.25 | C14: 8 | D14: =B14*C14 -> 1250 | E14: =SUM(D2:D24) -> 51250
A15: Móvil - Módulo de Sueño | B15: 156.25 | C15: 8 | D15: =B15*C15 -> 1250
A16: Móvil - Módulo de Entrenamiento | B16: 156.25 | C16: 16 | D16: =B16*C16 -> 2500
A17: Móvil - Módulo de Pacientes | B17: 156.25 | C17: 8 | D17: =B17*C17 -> 1250
A18: Móvil - Restablecer Contraseña | B18: 156.25 | C18: 8 | D18: =B18*C18 -> 1250
A19: Móvil - Módulo de Notificaciones | B19: 156.25 | C19: 8 | D19: =B19*C19 -> 1250 | E19: =SUM(D8:D19) -> 16875
A20: Móvil - Corrección de Diseños de Pantallas | B20: 156.25 | C20: 24 | D20: =B20*C20 -> 3750
A21: Back-End-Realización de base de datos con JPA | B21: 156.25 | C21: 52 | D21: =B21*C21 -> 8125
A22: Móvil - Inicio de sesión | B22: 156.25 | C22: 20 | D22: =B22*C22 -> 3125
A23: Móvil - Gestión de perfil | B23: 156.25 | C23: 12 | D23: =B23*C23 -> 1875
A24: Móvil - Registro de Usuario | B24: 156.25 | C24: 20 | D24: =B24*C24 -> 3125
A25: Móvil - Módulo del Perfil de Usuario | B25: 156.25 | C25: 12 | D25: =B25*C25 -> 1875
A26: Móvil - Pantalla Principal | B26: 156.25 | C26: 20 | D26: =B26*C26 -> 3125
A27: Móvil - Módulo de Alimentación | B27: 156.25 | C27: 12 | D27: =B27*C27 -> 1875
A28: Móvil - Módulo de Sueño | B28: 156.25 | C28: 20 | D28: =B28*C28 -> 3125
A29: Móvil - Módulo de Entrenamiento | B29: 156.25 | C29: 12 | D29: =B29*C29 -> 1875
A30: Móvil - Módulo de Pacientes | B30: 156.25 | C30: 12 | D30: =B30*C30 -> 1875
A31: Móvil - Restablecer Contraseña | B31: 156.25 | C31: 20 | D31: =B31*C31 -> 3125
A32: Móvil - Módulo de Notificaciones | B32: 156.25 | C32: 12 | D32: =B32*C32 -> 1875 | E32: =SUM(D20:D32) -> 38750
A33: Pruebas - Gestión de Usuarios | B33: 156.25 | C33: 12 | D33: =B33*C33 -> 1875
A34: Pruebas - Gestión de Horarios de Alimentos | B34: 156.25 | C34: 12 | D34: =B34*C34 -> 1875
A35: Pruebas - Gestión de Alimentos | B35: 156.25 | C35: 20 | D35: =B35*C35 -> 3125
A36: Pruebas - Gestion de Horarios de sueño | B36: 156.25 | C36: 12 | D36: =B36*C36 -> 1875
A37: Pruebas - Gestión de Ejercicio | B37: 156.25 | C37: 20 | D37: =B37*C37 -> 3125 | E37: =SUM(D33:D38) -> 13750
A38: Gestión de Notificaciones | B38: 156.25 | C38: 12 | D38: =B38*C38 -> 1875
A39: Documentacion Técnica | B39: 156.25 | C39: 20 | D39: =B39*C39 -> 3125
C40: Total | D40: =SUM(D2:D39) -> 86875
...

Sheet Riesgos Identificados
A1: Riesgo | B1: Probabilidad | C1: Impacto | D1: Respuesta | E1: Responsable
A2: Fallo en el despliegue por mala configuración(Backend) | B2: Alta | C2: Alta | D2: Mitigar | E2: Dev-Back
A3: Fallo en el despliegue por mala configuración(Frontend) | B3: Alta | C3: Alta | D3: Mitigar | E3: Dev-front
A4: Vulnerabilidad por falta de validaciones | B4: Alta | C4: Alto | D4: Aceptar | E4: Cliente / Líder
A5: Bug crítico en el código | B5: Media | C5: Alto | D5: Transferir | E5: Equipo de desarrollo
A6: Conflictos de merge en el repositorio | B6: Alta | C6: Alta | D6: Evitar | E6: Equipo de desarrollo
A7: Problemas en el envío de correos electrónicos para recuperación de cuenta | B7: Alta | C7: Media | D7: Mitigar | E7: Dev-Back
A8: Pérdida de datos por error humano o fallo de sistema | B8: Alta | C8: Alta | D8: Mitigar | E8: Equipo de desarrollo
A9: Cambios frecuentes en los requerimientos | B9: Alta | C9: Alta | D9: Mitigar | E9: Cliente / Líder
A10: Baja participación de usuarios en pruebas | B10: Media | C10: Baja | D10: Evitar | E10: Equipo de desarrollo
A11: Dificultades técnicas con integración de gráficos en PDF | B11: Media | C11: Media | D11: Evitar | E11: Equipo de desarrollo
